<?xml version="1.0"?>
<!-- Refactored by Arn-O -->
<robot name="youbot" xmlns:xacro="http://www.ros.org/wiki/xacro">

  <xacro:property name="M_PI" value="3.1415926535897931" /> 

  <!-- Import the spec provided by youBot store -->
  <xacro:include filename="$(find youbot_description)/urdf/spec.urdf.xacro" />

  <!-- Import all Gazebo-customization elements, including Gazebo colors -->
  <xacro:include filename="$(find youbot_description)/urdf/youbot.gazebo" />

  <xacro:macro name="youbot_description" >
    <!-- ### base ### -->
    <!-- footprint link -->
    <link name="base_footprint">
      <inertial>
        <mass value="0.001" />
        <inertia ixx="0.010" ixy="0.000" ixz="0.000" iyy="0.010" iyz="0.000" izz="0.010" />
      </inertial>

      <visual>
        <geometry>
          <box size="0.001 0.001 0.001" />
        </geometry> 
      </visual>
    </link>

    <!-- base link --> 
   <link name="base_link">
      <inertial>
        <mass value="${base_mass}" />      
        <inertia ixx="1.000" ixy="0.000" ixz="0.000" iyy="1.000" iyz="0.000" izz="1.000" />
      </inertial>

      <visual> 
        <geometry>
          <mesh filename="package://youbot_description/meshes/base_frame.dae"/>
        </geometry> 
      </visual>
    </link>

  <!-- base joint -->
    <joint name="base_joint" type="fixed">
      <origin xyz="${base_pose_x} ${base_pose_y} ${base_pose_z}" rpy="0 0 0" />
      <parent link="base_footprint"/>
      <child link="base_link" />
    </joint>

    <!-- ### wheels ### -->
    <!-- wheels -->
    <!-- TODO: replace the following 4 code blocks by macros -->
    <!-- front left wheel -->
    <link name="wheel_link_fl">
      <inertial>
        <mass value="${wheel_mass}" />
        <inertia  ixx="0.010" ixy="0.000" ixz="0.000" iyy="0.010" iyz="0.000" izz="0.010" />
      </inertial>

      <visual>
        <geometry>
          <sphere radius="${wheel_radius}" />
        </geometry>
      </visual>

      <collision>
        <geometry>
          <sphere radius="${wheel_radius}" />
        </geometry>
      </collision>
    </link>

    <!-- front right wheel -->
    <link name="wheel_link_fr">
      <inertial>
        <mass value="${wheel_mass}" />
        <inertia  ixx="0.010" ixy="0.000" ixz="0.000" iyy="0.010" iyz="0.000" izz="0.010" />
      </inertial>

      <visual>
        <geometry>
          <sphere radius="${wheel_radius}" />
        </geometry>
      </visual>

      <collision>
        <geometry>
          <sphere radius="${wheel_radius}" />
        </geometry>
      </collision>
    </link>

    <!-- back left wheel -->
    <link name="wheel_link_bl">
      <inertial>
        <mass value="${wheel_mass}" />
        <inertia  ixx="0.010" ixy="0.000" ixz="0.000" iyy="0.010" iyz="0.000" izz="0.010" />
      </inertial>

      <visual>
        <geometry>
          <sphere radius="${wheel_radius}" />
        </geometry>
      </visual>

      <collision>
        <geometry>
          <sphere radius="${wheel_radius}" />
        </geometry>
      </collision>
    </link>

    <!-- back right wheel -->
    <link name="wheel_link_br">
      <inertial>
        <mass value="${wheel_mass}" />
        <inertia  ixx="0.010" ixy="0.000" ixz="0.000" iyy="0.010" iyz="0.000" izz="0.010" />
      </inertial>

      <visual>
        <geometry>
          <sphere radius="${wheel_radius}" />
        </geometry>
      </visual>

      <collision>
        <geometry>
          <sphere radius="${wheel_radius}" />
        </geometry>
      </collision>
    </link>

  <!-- wheels joints -->
    <joint name="wheel_fl_joint" type="fixed">
      <origin xyz="${wheel_fl_pose_x} ${wheel_fl_pose_y} ${wheel_fl_pose_z}" rpy="0 0 0" />
      <parent link="base_link"/>
      <child link="wheel_link_fl" />
    </joint>

    <joint name="wheel_fr_joint" type="fixed">
      <origin xyz="${wheel_fr_pose_x} ${wheel_fr_pose_y} ${wheel_fr_pose_z}" rpy="0 0 0" />
      <parent link="base_link"/>
      <child link="wheel_link_fr" />
    </joint>

    <joint name="wheel_bl_joint" type="fixed">
      <origin xyz="${wheel_bl_pose_x} ${wheel_bl_pose_y} ${wheel_bl_pose_z}" rpy="0 0 0" />
      <parent link="base_link"/>
      <child link="wheel_link_bl" />
    </joint>

    <joint name="wheel_br_joint" type="fixed">
      <origin xyz="${wheel_br_pose_x} ${wheel_br_pose_y} ${wheel_br_pose_z}" rpy="0 0 0" />
      <parent link="base_link"/>
      <child link="wheel_link_br" />
    </joint> 	

  <!-- #### plate #### -->
  <!-- plate links -->
  <link name="plate_link">
    <inertial>
     <mass value="${plate_mass}"/>
     <inertia ixx="0.01" ixy="0" ixz="0" iyy="0.01" iyz="0" izz="0.01" />
    </inertial>
			
    <visual>
      <geometry>
        <mesh filename="package://youbot_description/meshes/plate.dae" />
      </geometry>
    </visual>
  </link>

  <!-- plate joint -->
    <joint name="plate_joint" type="fixed">
      <origin xyz="${plate_pose_x} ${plate_pose_y} ${plate_pose_z}" rpy="0 0 0" />
      <parent link="base_link"/>
      <child link="plate_link" />
    </joint>  

  <!-- ### arm_base ### -->
  <!-- arm_base link -->
    <link name="arm_base_link">
      <inertial>
        <mass value="${arm_base_mass}" />
        <inertia ixx="0.010" ixy="0.000" ixz="0.000" iyy="0.010" iyz="0.000" izz="0.010" />
      </inertial>

      <visual>
        <geometry>
          <mesh filename="package://youbot_description/meshes/arm_base_frame.dae"/>
        </geometry> 
      </visual>
    </link>

  <!-- arm_base joint -->
    <joint name="arm_base_joint" type="fixed">
      <origin xyz="${arm_base_pose_x} ${arm_base_pose_y} ${arm_base_pose_z}" rpy="0 0 0" />
      <parent link="base_link"/>
      <child link="arm_base_link" />
    </joint>   

  <!-- TODO: replace the next 5 code blocks by macro -->
  <!-- ### arm_1 ### -->
  <!-- arm_1 link -->
    <link name="arm_1_link">
      <inertial>
        <mass value="${arm_1_link_mass}" />
        <inertia ixx="0.010" ixy="0.000" ixz="0.000" iyy="0.010" iyz="0.000" izz="0.010" />
      </inertial>

      <visual>
        <geometry> 
          <mesh filename="package://youbot_description/meshes/arm_joint_1.dae"/>
        </geometry> 
      </visual>
    </link>

  <!-- arm_1 joint -->
    <joint name="arm_1_joint" type="revolute">
      <origin xyz="${arm_1_link_pose_x} ${arm_1_link_pose_y} ${arm_1_link_pose_z}" 
              rpy="${arm_1_link_orient_r} ${arm_1_link_orient_p} ${arm_1_link_orient_y}" />
      <parent link="arm_base_link"/>
      <child link="arm_1_link" />
      <axis xyz="${arm_1_axis}" />
      <limit lower="${arm_1_limit_min}" upper="${arm_1_limit_max}"
             effort="${arm_joint_effort}" velocity="${arm_joint_velocity}" />
    </joint> 

  <transmission name="tran1">
    <type>transmission_interface/SimpleTransmission</type>
    <joint name="arm_1_joint"/>
    <actuator name="motor1">
      <hardwareInterface>EffortJointInterface</hardwareInterface>
      <mechanicalReduction>1</mechanicalReduction>
    </actuator>
  </transmission>

  <!-- ### arm_2 ### -->
  <!-- arm_2 link -->
    <link name="arm_2_link">
      <inertial>
        <mass value="${arm_2_link_mass}" />
        <inertia ixx="0.010" ixy="0.000" ixz="0.000" iyy="0.010" iyz="0.000" izz="0.010" />
      </inertial>

      <visual>
        <geometry>
          <mesh filename="package://youbot_description/meshes/arm_joint_2.dae"/>
        </geometry> 
      </visual>
    </link>

  <!-- arm_2 joint -->
    <joint name="arm_2_joint" type="revolute">
      <origin xyz="${arm_2_link_pose_x} ${arm_2_link_pose_y} ${arm_2_link_pose_z}"
              rpy="${arm_2_link_orient_r} ${arm_2_link_orient_p} ${arm_2_link_orient_y}" />
      <parent link="arm_1_link"/>
      <child link="arm_2_link" />
      <axis xyz="${arm_2_axis}" />
      <limit lower="${arm_2_limit_min}" upper="${arm_2_limit_max}"
             effort="${arm_joint_effort}" velocity="${arm_joint_velocity}" />
    </joint>

  <!-- ### arm_3 ### -->
  <!-- arm_3 link -->
    <link name="arm_3_link">
      <inertial>
        <mass value="${arm_3_link_mass}" />
        <inertia ixx="0.010" ixy="0.000" ixz="0.000" iyy="0.010" iyz="0.000" izz="0.010" />
      </inertial>

      <visual>
        <geometry>
          <mesh filename="package://youbot_description/meshes/arm_joint_3.dae"/>
        </geometry> 
      </visual>
    </link>

  <!-- arm_3 joint -->
    <joint name="arm_3_joint" type="revolute">
      <origin xyz="${arm_3_link_pose_x} ${arm_3_link_pose_y} ${arm_3_link_pose_z}"
              rpy="${arm_3_link_orient_r} ${arm_3_link_orient_p} ${arm_3_link_orient_y}" />
      <parent link="arm_2_link"/>
      <child link="arm_3_link" />
      <axis xyz="${arm_3_axis}" />
      <limit lower="${arm_3_limit_min}" upper="${arm_3_limit_max}"
             effort="${arm_joint_effort}" velocity="${arm_joint_velocity}" />
    </joint>	

  <!-- ### arm_4 ### -->
  <!-- arm_4 link -->
    <link name="arm_4_link">
      <inertial>
        <mass value="${arm_4_link_mass}" />
        <inertia ixx="0.010" ixy="0.000" ixz="0.000" iyy="0.010" iyz="0.000" izz="0.010" />
      </inertial>

      <visual>
        <geometry>
          <mesh filename="package://youbot_description/meshes/arm_joint_4.dae"/>
        </geometry> 
      </visual>
    </link>

  <!-- arm_4 joint -->
    <joint name="arm_4_joint" type="revolute">
      <origin xyz="${arm_4_link_pose_x} ${arm_4_link_pose_y} ${arm_4_link_pose_z}"
              rpy="${arm_4_link_orient_r} ${arm_4_link_orient_p} ${arm_4_link_orient_y}" />
      <parent link="arm_3_link"/>
      <child link="arm_4_link" />
      <axis xyz="${arm_4_axis}" />
      <limit lower="${arm_4_limit_min}" upper="${arm_4_limit_max}"
             effort="${arm_joint_effort}" velocity="${arm_joint_velocity}" />
    </joint>

  <!-- ### arm_5 ### -->
  <!-- arm_5 link -->
    <link name="arm_5_link">
      <inertial>
        <mass value="${arm_5_link_mass}" />
        <inertia ixx="0.010" ixy="0.000" ixz="0.000" iyy="0.010" iyz="0.000" izz="0.010" />
      </inertial>

      <visual>
        <geometry>
          <mesh filename="package://youbot_description/meshes/arm_joint_5.dae"/>
        </geometry> 
      </visual>
    </link>

  <!-- arm_5 joint -->
    <joint name="arm_5_joint" type="revolute">
      <origin xyz="${arm_5_link_pose_x} ${arm_5_link_pose_y} ${arm_5_link_pose_z}"
              rpy="${arm_5_link_orient_r} ${arm_5_link_orient_p} ${arm_5_link_orient_y}" />
      <parent link="arm_4_link"/>
      <child link="arm_5_link" />
      <axis xyz="${arm_5_axis}" />
      <limit lower="${arm_5_limit_min}" upper="${arm_5_limit_max}"
             effort="${arm_joint_effort}" velocity="${arm_joint_velocity}" />
    </joint>	

  <!-- ### gripper_base ### -->
  <!-- gripper_base link -->
    <link name="gripper_base_link">
      <inertial>
        <mass value="${gripper_base_link_mass}" />
        <inertia ixx="0.010" ixy="0.000" ixz="0.000" iyy="0.010" iyz="0.000" izz="0.010" />
      </inertial>

      <visual>
        <geometry>
          <mesh filename="package://youbot_description/meshes/gripper_base_frame.dae"/>
        </geometry> 
      </visual>
    </link>

  <!-- gripper_base joint -->
    <joint name="gripper_base_joint" type="fixed">
      <origin xyz="${gripper_base_link_pose_x} ${gripper_base_link_pose_y} ${gripper_base_link_pose_z}"
              rpy="${gripper_base_link_orient_r} ${gripper_base_link_orient_p}
                                            ${gripper_base_link_orient_y}" />
      <parent link="arm_5_link"/>
      <child link="gripper_base_link" />
    </joint>

  <!-- ### finger_left ### -->
  <!-- finger_left link -->
    <link name="finger_left_link">
      <inertial>
        <mass value="${finger_left_link_mass}" />
        <inertia ixx="0.010" ixy="0.000" ixz="0.000" iyy="0.010" iyz="0.000" izz="0.010" />
      </inertial>

      <visual>
        <geometry>
          <mesh filename="package://youbot_description/meshes/gripper_left_finger.dae"/>
        </geometry> 
      </visual>
    </link>

  <!-- finger_left joint -->
    <joint name="finger_left_joint" type="prismatic">
      <origin xyz="${finger_left_link_pose_x} ${finger_left_link_pose_y} ${finger_left_link_pose_z}" />
      <parent link="gripper_base_link"/>
      <child link="finger_left_link" />
      <axis xyz="${finger_left_axis}" />
      <limit lower="${finger_left_limit_min}" upper="${finger_left_limit_max}"
             effort="${finger_joint_effort}" velocity="${finger_joint_velocity}" />
    </joint>
	
  <!-- ### finger_right ### -->
  <!-- finger_right link -->
    <link name="finger_right_link">
      <inertial>
        <mass value="${finger_right_link_mass}" />
        <inertia ixx="0.010" ixy="0.000" ixz="0.000" iyy="0.010" iyz="0.000" izz="0.010" />
      </inertial>

      <visual>
        <geometry>
          <mesh filename="package://youbot_description/meshes/gripper_right_finger.dae"/>
        </geometry> 
      </visual>
    </link>

  <!-- finger_right joint -->
    <joint name="finger_right_joint" type="prismatic">
      <origin xyz="${finger_right_link_pose_x} ${finger_right_link_pose_y}
                                                       ${finger_right_link_pose_z}" />
      <parent link="gripper_base_link"/>
      <child link="finger_left_link" />
      <axis xyz="${finger_left_axis}" />
      <limit lower="${finger_left_limit_min}" upper="${finger_left_limit_max}"
             effort="${finger_joint_effort}" velocity="${finger_joint_velocity}" />
    </joint>

  </xacro:macro> 

  <xacro:youbot_description />

</robot>
